# What

c++支持将产生的异常进行捕捉，由用户提供处理方式来避免崩溃。

# 语法

``try{...throw...}catch(...){...}catch(...){...}``

# Code

```c++
#include<iostream>
#include<exception>
#include<stdexcept>

using namespace std;
void throwException()
{
    try 
    {
        cout << "Function throwException throws an exception\n";
        throw exception("a exception from throwexception");
    }
    catch (exception& caughtException)
    {
        cout << "Exception handled in function throwException"
            << "\nfunction throwException rethrows exception";
        throw exception("a exception from throwexception");
    }
    cout << "This is also should not print\n";
}

int main()
{
    try 
    {
        cout << "\nmain invokes function theowException\n";
        throwException();
        cout << "This should not print\n";
    }
    catch (exception&caughtException) 
    {
        cout << "\n\nException handled in function main\n";
    }
    catch (runtime_error& error) 
    {
        cout << "Exception occurred:" << error.what() << endl;
    }
    cout << "Program control continues after the catch in main\n";

    return 0;
}

```

当一个函数没有接住异常时，异常将会返回调用它的上一级函数寻找catch，直到找到main函数。

